Workbook

Sheet Sheet1
A1: 订单日期 | B1: 订单号 | C1: 城市 | D1: 销售渠道 | E1: 产品名称 | F1: 类别 | G1: 数量 | H1: 单价 | I1: 销售额 | J1: 备注
A2: 46113 | B2: SO20357 | C2: 上海 | D2: 天猫 | E2: 空气净化器S1 | F2: 家电 | G2: 1 | H2: 1599 | I2: 1599
A3: 46117 | B3: SO20365 | C3: 深圳 | D3: 抖音 | E3: 智能手表ProX | F3: 数码 | G3: 3 | H3: 1299 | I3: 3897
A4: 46118 | B4: SO20263 | C4: 杭州 | D4: 官网 | E4: 无线耳机Air | F4: 数码 | G4: 2 | H4: 499 | I4: 998
A5: 46118 | B5: SO20281 | C5: 杭州 | D5: 官网 | E5: 无线耳机Air | F5: 数码 | G5: 1 | H5: 499 | I5: 499
A6: 46118 | B6: SO20340 | C6: 成都 | D6: 官网 | E6: 电动升降桌 | F6: 家居 | G6: 1 | H6: 2499 | I6: 2499 | J6: 赠品订单
A7: 46119 | B7: SO20352 | C7: 成都 | D7: 抖音 | E7: 人体工学椅 | F7: 家居 | G7: 1 | H7: 1899 | I7: 1899
A8: 46120 | B8: SO20299 | C8: 杭州 | D8: 官网 | E8: 人体工学椅 | F8: 家居 | G8: 2 | H8: 1899 | I8: 3798
A9: 46120 | B9: SO20307 | C9: 杭州 | D9: 官网 | E9: 无线耳机Air | F9: 数码 | G9: 2 | H9: 499 | I9: 998
A10: 46120 | B10: SO20342 | C10: 深圳 | D10: 天猫 | E10: 无线耳机Air | F10: 数码 | G10: 1 | H10: 499 | I10: 499 | J10: 赠品订单
A11: 46121 | B11: SO20323 | C11: 成都 | D11: 天猫 | E11: 便携咖啡机 | F11: 家电 | G11: 1 | H11: 899 | I11: 899
A12: 46121 | B12: SO20334 | C12: 北京 | D12: 抖音 | E12: 人体工学椅 | F12: 家居 | G12: 2 | H12: 1899 | I12: 3798
A13: 46122 | B13: SO20276 | C13: 杭州 | D13: 天猫 | E13: 空气净化器S1 | F13: 家电 | G13: 2 | H13: 1599 | I13: 3198
A14: 46122 | B14: SO20285 | C14: 成都 | D14: 线下门店 | E14: 人体工学椅 | F14: 家居 | G14: 1 | H14: 1899 | I14: 1899
A15: 46122 | B15: SO20327 | C15: 成都 | D15: 官网 | E15: 人体工学椅 | F15: 家居 | G15: 1 | H15: 1899 | I15: 1899 | J15: 已退款
A16: 46122 | B16: SO20362 | C16: 杭州 | D16: 京东 | E16: 无线耳机Air | F16: 数码 | G16: 1 | H16: 499 | I16: 499
A17: 46123 | B17: SO20266 | C17: 上海 | D17: 京东 | E17: 人体工学椅 | F17: 家居 | G17: 2 | H17: 1899 | I17: 3798
A18: 46123 | B18: SO20305 | C18: 北京 | D18: 官网 | E18: 空气净化器S1 | F18: 家电 | G18: 2 | H18: 1599 | I18: =G18*H18 -> 3198
A19: 46124 | B19: SO20329 | C19: 北京 | D19: 线下门店 | E19: 智能手表ProX | F19: 数码 | G19: 1 | H19: 1299 | I19: 1299
A20: 46126 | B20: SO20291 | C20: 深圳 | D20: 京东 | E20: 人体工学椅 | F20: 家居 | G20: 1 | H20: 1899 | I20: 1899
A21: 46127 | B21: SO20318 | C21: 北京 | D21: 官网 | E21: 电动升降桌 | F21: 家居 | G21: 1 | H21: 2499 | I21: 2499
A22: 46127 | B22: SO20330 | C22: 上海 | D22: 官网 | E22: 无线耳机Air | F22: 数码 | G22: 1 | H22: 499 | I22: 499
A23: 46128 | B23: SO20273 | C23: 北京 | D23: 天猫 | E23: 智能手表ProX | F23: 数码 | G23: 3 | H23: 1299 | I23: 3897
A24: 46128 | B24: SO20346 | C24: 成都 | D24: 天猫 | E24: 空气净化器S1 | F24: 家电 | G24: 1 | H24: 1599 | I24: 1599
A25: 46128 | B25: SO20359 | C25: 深圳 | D25: 抖音 | E25: 人体工学椅 | F25: 家居 | G25: 2 | H25: 1899 | I25: 3798
A26: 46130 | B26: SO20280 | C26: 广州 | D26: 官网 | E26: 人体工学椅 | F26: 家居 | G26: 2 | H26: 1899 | I26: 3798
A27: 46130 | B27: SO20282 | C27: 深圳 | D27: 线下门店 | E27: 人体工学椅 | F27: 家居 | G27: 1 | H27: 1899 | I27: 1899
A28: 46130 | B28: SO20304 | C28: 深圳 | D28: 京东 | E28: 空气净化器S1 | F28: 家电 | G28: 3 | H28: 1599 | I28: 4797
A29: 46130 | B29: SO20312 | C29: 北京 | D29: 天猫 | E29: 人体工学椅 | F29: 家居 | G29: 3 | H29: 1899 | I29: 5697
A30: 46131 | B30: SO20310 | C30: 广州 | D30: 抖音 | E30: 空气净化器S1 | F30: 家电 | G30: 1 | H30: 1599 | I30: 1599
... A45: 46139 | B45: SO20262 | C45: 深圳 | D45: 天猫 | E45: 人体工学椅 | F45: 家居 | G45: 1 | H45: 1899 | I45: 1899
A46: 46139 | B46: SO20320 | C46: 成都 | D46: 天猫 | E46: 人体工学椅 | F46: 家居 | G46: 1 | H46: 1899 | I46: 1899 | J46: 赠品订单
A47: 46140 | B47: SO20315 | C47: 成都 | D47: 京东 | E47: 人体工学椅 | F47: 家居 | G47: 1 | H47: 1899 | I47: 1899
A48: 46141 | B48: SO20272 | C48: 深圳 | D48: 线下门店 | E48: 人体工学椅 | F48: 家居 | G48: 2 | H48: 1899 | I48: 3798
A49: 46141 | B49: SO20296 | C49: 北京 | D49: 天猫 | E49: 智能手表ProX | F49: 数码 | G49: 3 | H49: 1299 | I49: 3897
A50: 46141 | B50: SO20331 | C50: 深圳 | D50: 京东 | E50: 人体工学椅 | F50: 家居 | G50: 1 | H50: 1899 | I50: 1899
A51: 46142 | B51: SO20294 | C51: 上海 | D51: 天猫 | E51: 人体工学椅 | F51: 家居 | G51: 2 | H51: 1899 | I51: 3798
A52: 46142 | B52: SO20302 | C52: 上海 | D52: 天猫 | E52: 无线耳机Air | F52: 数码 | G52: 1 | H52: 499 | I52: 499
A53: 46142 | B53: SO20343 | C53: 深圳 | D53: 天猫 | E53: 空气净化器S1 | F53: 家电 | G53: 3 | H53: 1599 | I53: 4797
A54: 46143 | B54: SO20375 | C54: 广州 | D54: 官网 | E54: 人体工学椅 | F54: 家居 | G54: 1 | H54: 1899 | I54: 1899
...

Sheet 数据透视表
A1: Sum of 销售额 | B1: 类别
A2: 城市 | B2: 家居 | C2: 家电 | D2: 数码 | E2: Grand Total
A3: 上海 | B3: 54174 | C3: 8194 | D3: 11889 | E3: 74257
A4: 北京 | B4: 35982 | C4: 7693 | D4: 18978 | E4: 62653
A5: 广州 | B5: 23289 | C5: 15187 | D5: 11588 | E5: 50064
A6: 成都 | B6: 39681 | C6: 11989 | D6: 18384 | E6: 70054
A7: 杭州 | B7: 39081 | C7: 16388 | D7: 16879 | E7: 72348
A8: 深圳 | B8: 42978 | C8: 32776 | D8: 10788 | E8: 86542
A9: Grand Total | B9: 235185 | C9: 92227 | D9: 88506 | E9: 415918

Sheet 汇总
A1: 月份 | B1: 销售额 | D1: 渠道 | E1: 销售额 | G1: 类别 | H1: 销售额
A2: 4月 | B2: =SUMPRODUCT((MONTH(Sheet1!$A$2:$A$181)=4)*Sheet1!$I$2:$I$181) -> 126619 | D2: 天猫 | E2: =SUMIF(Sheet1!$D$2:$D$181,D2,Sheet1!$I$2:$I$181) -> 103624 | G2: 家居 | H2: =SUMIF(Sheet1!$F$2:$F$181,G2,Sheet1!$I$2:$I$181) -> 235185
A3: 5月 | B3: =SUMPRODUCT((MONTH(Sheet1!$A$2:$A$181)=5)*Sheet1!$I$2:$I$181) -> 136305 | D3: 抖音 | E3: =SUMIF(Sheet1!$D$2:$D$181,D3,Sheet1!$I$2:$I$181) -> 67155 | G3: 家电 | H3: =SUMIF(Sheet1!$F$2:$F$181,G3,Sheet1!$I$2:$I$181) -> 92227
A4: 6月 | B4: =SUMPRODUCT((MONTH(Sheet1!$A$2:$A$181)=6)*Sheet1!$I$2:$I$181) -> 152994 | D4: 官网 | E4: =SUMIF(Sheet1!$D$2:$D$181,D4,Sheet1!$I$2:$I$181) -> 81839 | G4: 数码 | H4: =SUMIF(Sheet1!$F$2:$F$181,G4,Sheet1!$I$2:$I$181) -> 88506
D5: 京东 | E5: =SUMIF(Sheet1!$D$2:$D$181,D5,Sheet1!$I$2:$I$181) -> 70956
D6: 线下门店 | E6: =SUMIF(Sheet1!$D$2:$D$181,D6,Sheet1!$I$2:$I$181) -> 92344

Sheet 分析看板
A1: Q2 销售分析看板
A3: 本季度总销售额 | C3: 总订单数 | E3: 客单价
A4: =SUM(Sheet1!I2:I181) -> 415918 | C4: =COUNTA(Sheet1!B2:B181) -> 180 | E4: =SUM(Sheet1!I2:I181)/COUNTA(Sheet1!B2:B181) -> 2310.6556
